Workbook

Sheet Exec Summary
A2: Lead Conversion & Quality Analytics
A4: Metric | B4: Result | C4: Context | E4: Outcome bucket | F4: Leads | G4: Share | H4: Definition
A5: Total leads | B5: =Opportunity!B5 -> 3021 | C5: 2009-04-02 to 2009-09-30 | E5: Closed | F5: 245 | G5: =F5/$B$5 -> 0.081098974 | H5: Customer
A6: Closed leads | B6: =Opportunity!B6 -> 245 | C6: Primary success outcome | E6: Good progression | F6: 148 | G6: =F6/$B$5 -> 0.048990401 | H6: EP Sent/Received/Confirmed
A7: Baseline close rate | B7: =Opportunity!B7 -> 0.081098974 | C7: Unknown stays in denominator | E7: Bad quality | F7: 488 | G7: =F7/$B$5 -> 0.16153592 | H7: Unable to contact/invalid/does not qualify
A8: Target close rate | B8: =Opportunity!B8 -> 0.096 | C8: Assignment threshold | E8: Unknown | F8: 2140 | G8: =F8/$B$5 -> 0.70837471 | H8: Blank or neutral status
A9: Closes needed | B9: =Opportunity!B9 -> 291 | C9: Minimum whole-number target
A10: Additional closes | B10: =Opportunity!B10 -> 46 | C10: Gap to threshold
A11: Revenue uplift at $33 CPL | B11: =Opportunity!B5*(Opportunity!B12-Opportunity!B11) -> 9063 | C11: $30 to $33 is a 10% uplift
A14: Key findings
A15: Trend | B15: Close odds fell about 10.1% per 30 days (OR 0.899, 95% CI 0.829-0.974; p=0.009). Monthly heterogeneity p=0.0007.
A16: Segment | B16: Holding Tank - Debt closed at 14.50% (49/338) versus Student Debt at 1.11% (4/360). These are unadjusted associations.
A17: Opportunity | B17: The threshold requires 291 closes, 46 more than observed. The conservative ad-group mix test affects about 513 leads.
A18: Model | B18: The explanatory model has modest discrimination (temporal holdout AUC 0.609). Use it for hypothesis generation, not causal targeting.
A21: Recommended next steps
A22: 1 | B22: Run a staged traffic test that caps Student Debt and Credit Card Debt - high volume while expanding Holding Tank - Debt.
A23: 2 | B23: Monitor weekly close rate, lead mix, and score missingness; stop the test if the confidence interval or qualification mix deteriorates.

Sheet Data Cleaning
A2: Power Query cleaning and validation
A3: Check | B3: Source / expected | C3: Clean output | D3: Result | E3: What was done
A4: Lead rows | B4: 3021 | C4: =ROWS(LeadQualityCleaning[LeadKey]) -> 3021 | D4: =IF(B4=C4,"Matched","Check") -> Matched | E4: Kept every source record.
A5: Direct identifier columns | B5: 8 | C5: =COUNTIF(LeadQualityCleaning[#Headers],"Email")+COUNTIF(LeadQualityCleaning[#Headers],"FirstName")+COUNTIF(LeadQualityCleaning[#Headers],"IP Address")+COUNTIF(LeadQualityCleaning[#Headers],"Landing Page URL Parameters")+COUNTIF(LeadQualityCleaning[#Headers],"LandingPageURL")+COUNTIF(LeadQualityCleaning[#Headers],"ReferralURL")+COUNTIF(LeadQualityCleaning[#Headers],"ReferralURL Parameters")+COUNTIF(LeadQualityCleaning[#Headers],"SearchQuery") -> 0 | D5: =IF(C5=0,"Removed","Check") -> Removed | E5: Removed names, email, IP, search query, and detailed URL fields.
A6: IP referral values | B6: 2 | C6: =COUNTIF(LeadQualityCleaning[ReferralDomain],"IP literal redacted") -> 2 | D6: =IF(B6=C6,"Redacted","Check") -> Redacted | E6: Replaced both IP literals with the text IP literal redacted.
A7: Duplicate source ID rows | B7: 2 | C7: 0 | D7: =IF(C7=0,"Unique keys","Check") -> Unique keys | E7: Removed VendorLeadID and created a unique LeadKey.
A8: Missing LeadCreated values | B8: 0 | C8: =COUNTBLANK(LeadQualityCleaning[LeadCreated]) -> 0 | D8: =IF(C8=0,"Complete","Check") -> Complete | E8: Converted LeadCreated to a valid Excel date.
A9: Rows with an outcome group | B9: 3021 | C9: =COUNTA(LeadQualityCleaning[OutcomeBucket]) -> 3021 | D9: =IF(B9=C9,"Complete","Check") -> Complete | E9: Mapped every status to Closed, Good progression, Bad quality, or Unknown.
A10: Closed leads | B10: 245 | C10: =SUM(LeadQualityCleaning[IsClosed]) -> 245 | D10: =IF(B10=C10,"Matched","Check") -> Matched | E10: Created the IsClosed flag from CallStatus.
A11: Sanitized columns | B11: 24 | C11: 32 | D11: Prepared | E11: Removed 8 sensitive fields and added analysis fields for dates, outcomes, scores, and widgets.
A14: Step | B14: Fields | C14: Cleaning performed | D14: Output fields
A15: 1 | B15: Direct identifiers | C15: Dropped eight sensitive columns before creating analytical outputs. | D15: Sensitive fields excluded
A16: 2 | B16: VendorLeadID | C16: Replaced the source identifier with a deterministic anonymous key. | D16: LeadKey
A17: 3 | B17: Text fields | C17: Trimmed spaces and replaced blank text with Unknown. | D17: Standardized categories
A18: 4 | B18: ReferralDomain | C18: Detected complete IP-address values and redacted two records. | D18: ReferralDomain
A19: 5 | B19: LeadCreated | C19: Converted to date and created daily, weekly, and monthly fields. | D19: LeadDate, WeekStart, MonthStart, DaysSinceStart
A20: 6 | B20: CallStatus | C20: Grouped statuses and created simple 0/1 outcome flags. | D20: OutcomeBucket and outcome flags
A21: 7 | B21: AddressScore and PhoneScore | C21: Converted scores to numbers and kept missingness visible. | D21: Score bands and missing flags
A22: 8 | B22: WidgetName | C22: Corrected 300250 to 302252 and separated page and design details. | D22: WidgetNameNormalized, WidgetFormPages, WidgetDesign
A23: 9 | B23: Partner | C23: Standardized capitalization for the known partner values. | D23: Partner

Sheet Trends
A2: Lead quality trends
A4: Month | B4: Leads | C4: Closed | D4: Close rate | E4: Wilson low | F4: Wilson high | G4: Positive signal rate | H4: Target | J4: Test | K4: Estimate | L4: 95% low | M4: 95% high | N4: p-value | T4: Month label | U4: Close rate | V4: Target
A5: 39904 | B5: 518 | C5: 56 | D5: 0.10810811 | E5: 0.084195398 | F5: 0.13779053 | G5: 0.15250965 | H5: 0.096 | J5: Logistic linear time trend | K5: 0.89861554 | L5: 0.82904573 | M5: 0.97402333 | N5: 0.0093169619 | T5: Apr 2009 | U5: 0.10810811 | V5: 0.096
A6: 39934 | B6: 580 | C6: 37 | D6: 0.063793103 | E6: 0.046633305 | F6: 0.086693059 | G6: 0.10172414 | H6: 0.096 | J6: Monthly rate heterogeneity | K6: 21.488352 | N6: 0.00065480364 | T6: May 2009 | U6: 0.063793103 | V6: 0.096
A7: 39965 | B7: 609 | C7: 63 | D7: 0.10344828 | E7: 0.081694732 | F7: 0.13017321 | G7: 0.14121511 | H7: 0.096 | J7: First vs last month | K7: -0.064503457 | N7: 0.00074255504 | T7: Jun 2009 | U7: 0.10344828 | V7: 0.096
A8: 39995 | B8: 532 | C8: 33 | D8: 0.062030075 | E8: 0.044506665 | F8: 0.085833117 | G8: 0.092105263 | H8: 0.096 | T8: Jul 2009 | U8: 0.062030075 | V8: 0.096
A9: 40026 | B9: 438 | C9: 41 | D9: 0.093607306 | E9: 0.069751822 | F9: 0.12452931 | G9: 0.14155251 | H9: 0.096 | T9: Aug 2009 | U9: 0.093607306 | V9: 0.096
A10: 40057 | B10: 344 | C10: 15 | D10: 0.043604651 | E10: 0.026600369 | F10: 0.070689525 | G10: 0.16860465 | H10: 0.096 | T10: Sep 2009 | U10: 0.043604651 | V10: 0.096
A14: Week start | B14: Leads | C14: Closed | D14: Close rate | E14: Wilson low | F14: Wilson high | G14: Positive signal rate | H14: Target
A15: 39902 | B15: 37 | C15: 3 | D15: 0.081081081 | E15: 0.027960574 | F15: 0.21300679 | G15: 0.16216216 | H15: 0.096
A16: 39909 | B16: 119 | C16: 15 | D16: 0.12605042 | E16: 0.077897211 | F16: 0.19759169 | G16: 0.1512605 | H16: 0.096
A17: 39916 | B17: 125 | C17: 16 | D17: 0.128 | E17: 0.080347029 | F17: 0.19783562 | G17: 0.168 | H17: 0.096
A18: 39923 | B18: 155 | C18: 14 | D18: 0.090322581 | E18: 0.054565816 | F18: 0.14589481 | G18: 0.16129032 | H18: 0.096
A19: 39930 | B19: 129 | C19: 10 | D19: 0.07751938 | E19: 0.042649775 | F19: 0.13682325 | G19: 0.10852713 | H19: 0.096
A20: 39937 | B20: 113 | C20: 10 | D20: 0.088495575 | E20: 0.04877938 | F20: 0.15527027 | G20: 0.11504425 | H20: 0.096
A21: 39944 | B21: 166 | C21: 12 | D21: 0.072289157 | E21: 0.041833049 | F21: 0.12209312 | G21: 0.12650602 | H21: 0.096
A22: 39951 | B22: 122 | C22: 8 | D22: 0.06557377 | E22: 0.033598869 | F22: 0.12407142 | G22: 0.090163934 | H22: 0.096
A23: 39958 | B23: 132 | C23: 5 | D23: 0.037878788 | E23: 0.016286179 | F23: 0.085608036 | G23: 0.068181818 | H23: 0.096
A24: 39965 | B24: 137 | C24: 10 | D24: 0.072992701 | E24: 0.040128623 | F24: 0.12915008 | G24: 0.10218978 | H24: 0.096
A25: 39972 | B25: 165 | C25: 17 | D25: 0.1030303 | E25: 0.0653268 | F25: 0.15879741 | G25: 0.15151515 | H25: 0.096
A26: 39979 | B26: 153 | C26: 21 | D26: 0.1372549 | E26: 0.091556937 | F26: 0.20072203 | G26: 0.16339869 | H26: 0.096
... A41: 40084 | B41: 41 | C41: 0 | D41: 0 | E41: 0 | F41: 0.08566757 | G41: 0.14634146 | H41: 0.096

Sheet Segments
A2: Segment performance
A4: Ad group | B4: Leads | C4: Closed | D4: Close rate | E4: Wilson low | F4: Wilson high | G4: q-value | H4: Reliable n
A5: Holding Tank - Debt | B5: 338 | C5: 49 | D5: 0.14497041 | E5: 0.11142534 | F5: 0.18649481 | G5: 0.0002604243 | H5: Yes
A6: Consolidate | B6: 169 | C6: 21 | D6: 0.12426036 | E6: 0.082728505 | F6: 0.18249408 | G6: 0.3585627 | H6: Yes
A7: Debt | B7: 93 | C7: 11 | D7: 0.11827957 | E7: 0.067344378 | F7: 0.19949855 | G7: 0.82167284 | H7: Yes
A8: General Debt | B8: 130 | C8: 13 | D8: 0.1 | E8: 0.059375488 | F8: 0.16358576 | G8: 0.82167284 | H8: Yes
A9: Unknown | B9: 272 | C9: 26 | D9: 0.095588235 | E9: 0.066068167 | F9: 0.13637225 | G9: 0.82167284 | H9: Yes
A10: Debt Consolidation | B10: 195 | C10: 17 | D10: 0.087179487 | E10: 0.055142181 | F10: 0.13516752 | G10: 0.82167284 | H10: Yes
A11: How | B11: 115 | C11: 10 | D11: 0.086956522 | E11: 0.047918497 | F11: 0.15269717 | G11: 0.85564673 | H11: Yes
A12: Lower Payments | B12: 197 | C12: 10 | D12: 0.050761421 | E12: 0.027803154 | F12: 0.090904701 | G12: 0.71069929 | H12: Yes
A13: Credit Card Consolidation | B13: 84 | C13: 4 | D13: 0.047619048 | E13: 0.018671747 | F13: 0.11613315 | G13: 0.82167284 | H13: Yes
A14: Credit Card Debt - high volume | B14: 258 | C14: 12 | D14: 0.046511628 | E14: 0.026803871 | F14: 0.079525581 | G14: 0.3585627 | H14: Yes
A15: Student Debt | B15: 360 | C15: 4 | D15: 0.011111111 | E15: 0.0043291433 | F15: 0.028216512 | G15: 2.2702578e-05 | H15: Yes
A26: Dimension | B26: Segment | C26: Leads | D26: Closed | E26: Close rate | F26: Wilson low | G26: Wilson high | H26: Lift vs overall | I26: p-value | J26: q-value | K26: Reliable n
A27: Ad group | B27: Student Debt | C27: 360 | D27: 4 | E27: 0.011111111 | F27: 0.0043291433 | G27: 0.028216512 | H27: 0.1370068 | I27: 2.1829402e-07 | J27: 2.2702578e-05 | K27: Yes
A28: Ad group | B28: Holding Tank - Debt | C28: 338 | D28: 49 | E28: 0.14497041 | F28: 0.11142534 | G28: 0.18649481 | H28: 1.787574 | I28: 5.0081596e-06 | J28: 0.0002604243 | K28: Yes
A29: Ad group | B29: Unknown | C29: 272 | D29: 26 | E29: 0.095588235 | F29: 0.066068167 | G29: 0.13637225 | H29: 1.1786615 | I29: 0.3588026 | J29: 0.82167284 | K29: Yes
A30: Ad group | B30: Credit Card Debt - high volume | C30: 258 | D30: 12 | E30: 0.046511628 | F30: 0.026803871 | G30: 0.079525581 | H30: 0.57351685 | I30: 0.033337758 | J30: 0.3585627 | K30: Yes
A31: Ad group | B31: Lower Payments | C31: 197 | D31: 10 | E31: 0.050761421 | F31: 0.027803154 | G31: 0.090904701 | H31: 0.6259194 | I31: 0.10667976 | J31: 0.71069929 | K31: Yes
A32: Ad group | B32: Debt Consolidation | C32: 195 | D32: 17 | E32: 0.087179487 | F32: 0.055142181 | G32: 0.13516752 | H32: 1.0749765 | I32: 0.74776206 | J32: 0.82167284 | K32: Yes
A33: Ad group | B33: Consolidate | C33: 169 | D33: 21 | E33: 0.12426036 | F33: 0.082728505 | G33: 0.18249408 | H33: 1.5322063 | I33: 0.034393904 | J33: 0.3585627 | K33: Yes
A34: Ad group | B34: General Debt | C34: 130 | D34: 13 | E34: 0.1 | F34: 0.059375488 | G34: 0.16358576 | H34: 1.2330612 | I34: 0.4196742 | J34: 0.82167284 | K34: Yes
A35: Ad group | B35: How | C35: 115 | D35: 10 | E35: 0.086956522 | F35: 0.047918497 | G35: 0.15269717 | H35: 1.0722272 | I35: 0.81450987 | J35: 0.85564673 | K35: Yes
A36: Ad group | B36: Debt | C36: 93 | D36: 11 | E36: 0.11827957 | F36: 0.067344378 | G36: 0.19949855 | H36: 1.4584595 | I36: 0.18215376 | J36: 0.82167284 | K36: Yes
A37: Ad group | B37: Credit Card Consolidation | C37: 84 | D37: 4 | E37: 0.047619048 | F37: 0.018671747 | G37: 0.11613315 | H37: 0.58717201 | I37: 0.25428562 | J37: 0.82167284 | K37: Yes
A38: Address score band | B38: Missing | C38: 1850 | D38: 166 | E38: 0.08972973 | F38: 0.077542492 | G38: 0.10361726 | H38: 1.1064225 | I38: 0.028948603 | J38: 0.11579441 | K38: Yes
... A115: Widget pages | B115: 2DC | C115: 162 | D115: 12 | E115: 0.074074074 | F115: 0.04287845 | G115: 0.12500152 | H115: 0.91337868 | I115: 0.73635431 | J115: 0.73635431 | K115: Yes

Sheet Opportunity
A2: Opportunity calculations
A4: Assumption | B4: Value | C4: Definition
A5: Total leads | B5: =SUM(Trends!B5:B10) -> 3021 | C5: All leads; Unknown remains in denominator.
A6: Current closes | B6: =SUM(Trends!C5:C10) -> 245 | C6: Closed outcomes.
A7: Current close rate | B7: =B6/B5 -> 0.081098974 | C7: Closed / all leads.
A8: Target close rate | B8: =9.6% -> 0.096 | C8: Assignment threshold.
A9: Minimum target closes | B9: =ROUNDUP(B5*B8,0) -> 291 | C9: Ceiling(total leads x target rate).
A10: Incremental closes needed | B10: =B9-B6 -> 46 | C10: Minimum additional closes.
A11: Baseline CPL | B11: =30 -> 30 | C11: Assignment baseline.
A12: Stated offered CPL | B12: =33 -> 33 | C12: Explicit offer; equals a 10% uplift.
A15: Scenario | B15: Leads affected | C15: Destination rate | D15: Incremental closes | E15: Total closes | F15: Close rate | G15: Meets target | H15: Assumption
A16: Portfolio conversion target | B16: 3021 | C16: 0.096 | D16: 46 | E16: =$B$6+D16 -> 291 | F16: =E16/$B$5 -> 0.09632572 | G16: =IF(E16>=$B$9,"Yes","No") -> Yes | H16: Improve conversion across the portfolio; operational mechanism must be tested.
A17: Observed ad-group mix test | B17: 344 | C17: 0.14497041 | D17: 46.0476 | E17: =$B$6+D17 -> 291.0476 | F17: =E17/$B$5 -> 0.096341476 | G17: =IF(E17>=$B$9,"Yes","No") -> Yes | H17: Shift 344 Student Debt leads to Holding Tank - Debt at observed rates. Association may not persist after reallocation.
A18: Conservative ad-group mix test | B18: 513 | C18: 0.11142534 | D18: 46 | E18: =$B$6+D18 -> 291 | F18: =E18/$B$5 -> 0.09632572 | G18: =IF(E18>=$B$9,"Yes","No") -> Yes | H18: Shift Student Debt (360 leads), then Credit Card Debt - high volume (153 leads) to Holding Tank - Debt using its 95% Wilson lower bound. Validate with a randomized or staged test.
A23: Dimension | B23: Benchmark segment | C23: Observed rate | D23: Planning rate | E23: Potential closes | G23: Interpretation
A24: Marketing campaign | B24: Debt Holding Tank | C24: 0.14497041 | D24: 0.11142534 | E24: 100.83825 | G24: Dimension totals overlap and must not be added together.
A25: Ad group | B25: Holding Tank - Debt | C25: 0.14497041 | D25: 0.11142534 | E25: 83.50623 | G25: Planning rates use the benchmark segment's 95% Wilson lower bound.
A26: Debt level | B26: 70001-90000 | C26: 0.13740458 | D26: 0.088714816 | E26: 38.850342 | G26: Validate any reallocation through a staged or randomized traffic test.
A27: Widget | B27: w-302252-DebtReduction1-1DC-BlueMeter | C27: 0.14130435 | D27: 0.084476934 | E27: 22.399423 | G27: The stated $30 to $33 offer is a 10% increase; $36 is the literal 20% sensitivity.
A28: Phone score band | B28: Missing | C28: 0.091523342 | D28: 0.078461457 | E28: 18.729168
A29: Partner | B29: AdKnowledge | C29: 0.12280702 | D29: 0.081743307 | E29: 13.570759
A30: Address score band | B30: Missing | C30: 0.08972973 | D30: 0.077542492 | E30: 11.802258
A31: Widget design | B31: Base / unspecified | C31: 0.091935484 | D31: 0.071636328 | E31: 2.9923528
A32: Advertiser campaign | B32: Debt Settlement1 Master | C32: 0.083195592 | D32: 0.071353141 | E32: 0
A33: Publisher channel | B33: DebtReductionInc | C33: 0.079636364 | D33: 0.070094295 | E33: 0
A34: Publisher zone | B34: TopLeft-302252 | C34: 0.079636364 | D34: 0.070094295 | E34: 0
A35: Widget pages | B35: 1DC | C35: 0.081497027 | D35: 0.072020725 | E35: 0

Sheet Model
A2: Explanatory model and stability checks
A4: Metric | B4: Value | C4: Notes | J4: Model scope
A5: Observations | B5: 3021 | C5: All sanitized leads. | J5: Outcome | K5: Closed vs all other outcomes
A6: Events | B6: 245 | C6: Closed leads. | J6: Controls | K6: Time, address/phone scores and missingness, widget pages/design, publisher channel, debt level
A7: Parameters | B7: 25 | C7: Includes intercept and encoded categories. | J7: Excluded redundancy | K7: Publisher zone, advertiser campaign, and Partner proxies were excluded from the same equation to avoid exact collinearity.
A8: Design matrix rank | B8: 25 | C8: Should equal parameter count. | J8: Causal limit | K8: Adjusted odds ratios describe association among observed fields. They do not identify intervention effects.
A9: Events per parameter | B9: 9.8 | C9: Model complexity check. | J9: Reference levels | K9: Terms are relative to the model's omitted categorical level; review the full exported coefficient table for exact coding.
A10: In-sample AUC | B10: 0.62424131 | C10: Discrimination, not causal evidence. | J10: Missingness | K10: Score missingness is time-dependent and is modeled explicitly.
A11: In-sample Brier score | B11: 0.073488843 | C11: Lower is better. | J11: Validation | K11: Temporal holdout performance is modest, so use the model to prioritize tests rather than score individual leads.
A12: Temporal holdout observations | B12: 592 | C12: After 2009-08-13.
A13: Temporal holdout events | B13: 31 | C13: Closed leads in holdout.
A14: Temporal holdout AUC | B14: 0.60907941 | C14: Fit on first 80% by time.
A15: Temporal holdout Brier score | B15: 0.051009554 | C15: Fit on first 80% by time.
A16: Successful bootstrap fits | B16: 100 | C16: Out of 100 resamples.
A17: Converged | B17: 1 | C17: Statsmodels GLM convergence flag.
A20: Term | B20: Odds ratio | C20: 95% low | D20: 95% high | E20: p-value | F20: q-value | G20: Bootstrap sign consistency | H20: Interpretation
A21: C(DebtLevel)[T.7500-10000] | B21: 0.38063121 | C21: 0.21708767 | D21: 0.6673807 | E21: 0.00074769938 | F21: 0.0093462422 | G21: 1 | H21: Stable adjusted association
A22: C(DebtLevel)[T.More_than_100000] | B22: 0.23337725 | C22: 0.10099494 | D22: 0.53928384 | E22: 0.00066175025 | F22: 0.0093462422 | G22: 1 | H22: Stable adjusted association
A23: C(DebtLevel)[T.7500-15000] | B23: 0.37989512 | C23: 0.2011212 | D23: 0.71757877 | E23: 0.0028570185 | F23: 0.017856366 | G23: 1 | H23: Stable adjusted association
A24: C(DebtLevel)[T.30001-50000] | B24: 0.52910423 | C24: 0.32092654 | D24: 0.87232201 | E24: 0.012580043 | F24: 0.062900216 | G24: 1 | H24: Exploratory / unstable
A25: PhoneScoreFilled | B25: 1.2502494 | C25: 1.0203324 | D25: 1.5319748 | E25: 0.031232435 | F25: 0.13013514 | G25: 1 | H25: Exploratory / unstable
A26: C(DebtLevel)[T.15001-20000] | B26: 0.59067904 | C26: 0.35298141 | D26: 0.98844222 | E26: 0.045046663 | F26: 0.16088094 | G26: 0.99 | H26: Exploratory / unstable
A27: C(DebtLevel)[T.20001-30000] | B27: 0.61967502 | C27: 0.37777164 | D27: 1.0164795 | E27: 0.058061612 | F27: 0.18144254 | G27: 0.96 | H27: Exploratory / unstable
A28: C(DebtLevel)[T.50001-70000] | B28: 0.61876958 | C28: 0.34843342 | D28: 1.0988492 | E28: 0.10136856 | F28: 0.28157934 | G28: 0.96 | H28: Exploratory / unstable
A29: Time30Days | B29: 0.85671486 | C29: 0.69278332 | D29: 1.0594371 | E29: 0.15353756 | F29: 0.38384389 | G29: 0.93 | H29: Exploratory / unstable
A30: C(WidgetFormPages)[T.2DC] | B30: 0.60446638 | C30: 0.29307031 | D30: 1.2467302 | E30: 0.1729075 | F30: 0.39297158 | G30: 0.95 | H30: Exploratory / unstable
A31: C(WidgetDesign)[T.Head3] | B31: 0.53365579 | C31: 0.18214295 | D31: 1.5635439 | E31: 0.25219474 | F31: 0.52540571 | G31: 0.92 | H31: Exploratory / unstable
A32: C(PublisherCampaignName)[T.DebtReductionInc] | B32: 0.76893728 | C32: 0.45531088 | D32: 1.2985952 | E32: 0.32574649 | F32: 0.61261425 | G32: 0.8 | H32: Exploratory / unstable
... A44: C(DebtLevel)[T.70001-90000] | B44: 0.99603166 | C44: 0.53704442 | D44: 1.8472942 | E44: 0.98993364 | F44: 0.98993364 | G44: 0.51 | H44: Exploratory / unstable

Sheet QA
A2: Reconciliation and privacy checks
A4: Check | B4: Actual | C4: Expected | D4: Passed | E4: Notes
A5: Total lead count | B5: 3021 | C5: 3021 | D5: Yes
A6: Closed lead count | B6: 245 | C6: 245 | D6: Yes
A7: Baseline close rate | B7: 0.081098974 | C7: 0.081098974 | D7: Yes
A8: Status buckets reconcile | B8: 3021 | C8: 3021 | D8: Yes
A9: Outcome buckets sum to total | B9: 3021 | C9: 3021 | D9: Yes
A10: LeadKey uniqueness | B10: 3021 | C10: 3021 | D10: Yes | E10: Source vendor IDs: 8 missing; 1 duplicated nonblank value.
A11: PII columns absent downstream | B11: 0 | C11: 0 | D11: Yes | E11: Names, emails, IP, search query, and detailed URL fields removed.
A12: Sensitive values absent downstream | B12: 0 | C12: 0 | D12: Yes | E12: Value-level scan passed after redacting 2 IP-literal referral domains.
A13: VendorLeadID absent downstream | B13: 0 | C13: 0 | D13: Yes
A14: Target closes arithmetic | B14: 291 | C14: 291 | D14: Yes
A15: Incremental closes arithmetic | B15: 46 | C15: 46 | D15: Yes
A16: Minimum achieved rate meets target | B16: 0.09632572 | C16: 0.096 | D16: Yes
A17: All target scenarios meet threshold | B17: 3 | C17: 3 | D17: Yes
A18: Widget sizes normalized | B18: 0 | C18: 0 | D18: Yes
A19: Source schema includes expected PII | B19: 8 | C19: 8 | D19: Yes
A22: Required controls
A23: Status denominator | B23: Unknown and blank CallStatus rows remain in all-lead denominators.
A24: Privacy | B24: Names, emails, IP, VendorLeadID, search query, and detailed URL fields are absent downstream.
A25: Source integrity | B25: The original .xls is preserved unchanged under data/source/.

Sheet Clean Leads
A1: Clean leads from Power Query
A2: Refresh LeadQualityCleaning to reproduce the 3,021-row analytical table from the privacy-safe staging data.
A3: LeadKey | B3: LeadCreated | C3: LeadDate | D3: WeekStart | E3: MonthStart | F3: DaysSinceStart | G3: CallStatus | H3: OutcomeBucket | I3: IsClosed | J3: IsGoodProgression | K3: IsBadQuality | L3: IsUnknown | M3: IsPositiveSignal | N3: WidgetNameNormalized | O3: WidgetFormPages | P3: WidgetDesign | Q3: PublisherZoneName | R3: PublisherCampaignName | S3: AddressScore | T3: AddressScoreBand | U3: AddressScoreMissing | V3: PhoneScore | W3: PhoneScoreBand | X3: PhoneScoreMissing | Y3: AdvertiserCampaignName | Z3: State | AA3: DebtLevel | AB3: Partner | AC3: ReferralDomain | AD3: MarketingCampaign | AE3: AdGroup | AF3: Keyword
A4: LQ-D0054C82A74FA8B8 | B4: 39995 | C4: 39995 | D4: 39993 | E4: 39995 | F4: 90 | G4: Unknown | H4: Unknown | I4: 0 | J4: 0 | K4: 0 | L4: 1 | M4: 0 | N4: w-302252-DebtReduction1-1DC-CreditSolutions | O4: 1DC | P4: CreditSolutions | Q4: TopLeft-302252 | R4: DebtReductionInc | T4: Missing | U4: 1 | V4: 5 | W4: High (5) | X4: 0 | Y4: creditsolutions-branded-shortform | Z4: HI | AA4: 30001-50000 | AB4: Google | AC4: www.google.com | AD4: Debt Holding Tank | AE4: Holding Tank - Debt | AF4: Debt specialists
A5: LQ-27965EA801BA046F | B5: 39916 | C5: 39916 | D5: 39916 | E5: 39904 | F5: 11 | G5: Unknown | H5: Unknown | I5: 0 | J5: 0 | K5: 0 | L5: 1 | M5: 0 | N5: w-302252-DebtReduction1-1DC-Head2 | O5: 1DC | P5: Head2 | Q5: TopLeft-302252 | R5: DebtReductionInc | T5: Missing | U5: 1 | W5: Missing | X5: 1 | Y5: Debt Settlement1 Master | Z5: AL | AA5: 90000-100000 | AB5: AdKnowledge | AC5: Unknown | AD5: Financial Services | AE5: Consolidate | AF5: Unknown
A6: LQ-38BE97E34DFD8509 | B6: 39924 | C6: 39924 | D6: 39923 | E6: 39904 | F6: 19 | G6: Unable to contact - Bad Contact Information | H6: Bad quality | I6: 0 | J6: 0 | K6: 1 | L6: 0 | M6: 0 | N6: w-302252-DebtReduction1-1DC-Head2 | O6: 1DC | P6: Head2 | Q6: TopLeft-302252 | R6: DebtReductionInc | T6: Missing | U6: 1 | W6: Missing | X6: 1 | Y6: Debt Settlement1 Master | Z6: NY | AA6: 20001-30000 | AB6: AdKnowledge | AC6: us.mc582.mail.yahoo.com | AD6: Financial Services | AE6: Consolidate | AF6: Unknown
A7: LQ-FF0557178162A589 | B7: 40028 | C7: 40028 | D7: 40028 | E7: 40026 | F7: 123 | G7: Contacted - Doesn't Qualify | H7: Bad quality | I7: 0 | J7: 0 | K7: 1 | L7: 0 | M7: 0 | N7: w-302252-DebtReduction1-1DC-white | O7: 1DC | P7: white | Q7: TopLeft-302252 | R7: DebtReductionInc | S7: 5 | T7: High (5) | U7: 0 | V7: 3 | W7: Medium (3-4) | X7: 0 | Y7: Debt Settlement1 Master | Z7: WA | AA7: 20001-30000 | AB7: Google | AC7: norwich.kijiji.com | AD7: DebtReductionInc | AE7: Lower Payments | AF7: Unknown
A8: LQ-0F1EB50543FFF1B9 | B8: 39916 | C8: 39916 | D8: 39916 | E8: 39904 | F8: 11 | G8: Unknown | H8: Unknown | I8: 0 | J8: 0 | K8: 0 | L8: 1 | M8: 0 | N8: w-302252-DebtReduction1-1DC-BlueMeter | O8: 1DC | P8: BlueMeter | Q8: TopLeft-302252 | R8: DebtReductionInc | T8: Missing | U8: 1 | W8: Missing | X8: 1 | Y8: Debt Settlement1 Master | Z8: TX | AA8: More_than_100000 | AB8: Google | AC8: Unknown | AD8: DebtReductionInc | AE8: Debt Reduction | AF8: Unknown
A9: LQ-7264D0BE150739B2 | B9: 40023 | C9: 40023 | D9: 40021 | E9: 39995 | F9: 118 | G9: Unknown | H9: Unknown | I9: 0 | J9: 0 | K9: 0 | L9: 1 | M9: 0 | N9: w-302252-DebtReduction1-1DC-white | O9: 1DC | P9: white | Q9: TopLeft-302252 | R9: DebtReductionInc | S9: 5 | T9: High (5) | U9: 0 | V9: 3 | W9: Medium (3-4) | X9: 0 | Y9: Debt Settlement1 Master | Z9: CO | AA9: 10001-15000 | AB9: Google | AC9: googleads.g.doubleclick.net | AD9: DebtReductionInc | AE9: Credit Card Debt - high volume | AF9: Unknown
A10: LQ-DDC8A88AB95B9603 | B10: 40000 | C10: 40000 | D10: 40000 | E10: 39995 | F10: 95 | G10: Unknown | H10: Unknown | I10: 0 | J10: 0 | K10: 0 | L10: 1 | M10: 0 | N10: w-302252-DebtReduction1-1DC-white | O10: 1DC | P10: white | Q10: TopLeft-302252 | R10: DebtReductionInc | T10: Missing | U10: 1 | V10: 4 | W10: Medium (3-4) | X10: 0 | Y10: Debt Settlement1 Master | Z10: MI | AA10: 70001-90000 | AB10: Google | AC10: googleads.g.doubleclick.net | AD10: DebtReductionInc | AE10: Student Debt | AF10: Unknown
A11: LQ-9A6852DEC3381AFC | B11: 39925 | C11: 39925 | D11: 39923 | E11: 39904 | F11: 20 | G11: Unable to contact - Bad Contact Information | H11: Bad quality | I11: 0 | J11: 0 | K11: 1 | L11: 0 | M11: 0 | N11: w-302252-DebtReduction1-2DC-BlueMeter | O11: 2DC | P11: BlueMeter | Q11: TopLeft-302252 | R11: DebtReductionInc | T11: Missing | U11: 1 | W11: Missing | X11: 1 | Y11: Debt Settlement1 Master | Z11: IA | AA11: 7500-15000 | AB11: Google | AC11: www.google.com | AD11: Credit | AE11: Debt Credit Services | AF11: Credit services
A12: LQ-742F04170337A31C | B12: 39938 | C12: 39938 | D12: 39937 | E12: 39934 | F12: 33 | G12: Unknown | H12: Unknown | I12: 0 | J12: 0 | K12: 0 | L12: 1 | M12: 0 | N12: w-302252-DebtReduction1-1DC-Head3 | O12: 1DC | P12: Head3 | Q12: TopLeft-302252 | R12: DebtReductionInc | T12: Missing | U12: 1 | W12: Missing | X12: 1 | Y12: Debt Settlement1 Master | Z12: LA | AA12: 20001-30000 | AB12: Yahoo | AC12: dir.yahoo.com | AD12: DebtReductionInc | AE12: Debt Consolidation | AF12: Unknown
A13: LQ-1C6E4B5F99D1DD71 | B13: 40032 | C13: 40032 | D13: 40028 | E13: 40026 | F13: 127 | G13: Unknown | H13: Unknown | I13: 0 | J13: 0 | K13: 0 | L13: 1 | M13: 0 | N13: w-302252-DebtReduction1-1DC-CreditSolutions | O13: 1DC | P13: CreditSolutions | Q13: TopLeft-302252 | R13: DebtReductionInc | S13: 3 | T13: Medium (3-4) | U13: 0 | V13: 4 | W13: Medium (3-4) | X13: 0 | Y13: creditsolutions-branded-shortform | Z13: MI | AA13: 10001-15000 | AB13: Google | AC13: www.docstoc.com | AD13: Debt Volume_MI | AE13: Settlement | AF13: Debt settlement
A14: LQ-A341D8692CD03D91 | B14: 39965 | C14: 39965 | D14: 39965 | E14: 39965 | F14: 60 | G14: Unable to contact - Bad Contact Information | H14: Bad quality | I14: 0 | J14: 0 | K14: 1 | L14: 0 | M14: 0 | N14: w-302252-DebtReduction1-1DC-CreditSolutions | O14: 1DC | P14: CreditSolutions | Q14: TopLeft-302252 | R14: DebtReductionInc | T14: Missing | U14: 1 | W14: Missing | X14: 1 | Y14: creditsolutions-branded-shortform | Z14: TX | AA14: 20001-30000 | AB14: Google | AC14: googleads.g.doubleclick.net | AD14: DebtReductionInc | AE14: Credit Card Debt - high volume | AF14: Unknown
A15: LQ-D322F0EE3EE5476A | B15: 40020 | C15: 40020 | D15: 40014 | E15: 39995 | F15: 115 | G15: Unknown | H15: Unknown | I15: 0 | J15: 0 | K15: 0 | L15: 1 | M15: 0 | N15: w-302252-DebtReduction1-1DC-CreditSolutions | O15: 1DC | P15: CreditSolutions | Q15: TopLeft-302252 | R15: DebtReductionInc | S15: 5 | T15: High (5) | U15: 0 | V15: 5 | W15: High (5) | X15: 0 | Y15: creditsolutions-branded-shortform | Z15: IL | AA15: 30001-50000 | AB15: Google | AC15: www.google.com | AD15: Debt Volume | AE15: Debt | AF15: Debt
A16: LQ-E477F03E3D0A0344 | B16: 39957 | C16: 39957 | D16: 39951 | E16: 39934 | F16: 52 | G16: Unknown | H16: Unknown | I16: 0 | J16: 0 | K16: 0 | L16: 1 | M16: 0 | N16: w-302252-DebtReduction1-1DC | O16: 1DC | P16: Base / unspecified | Q16: TopLeft-302252 | R16: DebtReductionInc | T16: Missing | U16: 1 | W16: Missing | X16: 1 | Y16: Debt Settlement1 Master | Z16: MI | AA16: 15001-20000 | AB16: Yahoo | AC16: search.yahoo.com | AD16: state | AE16: Debt Settlement Companies | AF16: Unknown
A17: LQ-3429F31F72D06F42 | B17: 39957 | C17: 39957 | D17: 39951 | E17: 39934 | F17: 52 | G17: Unknown | H17: Unknown | I17: 0 | J17: 0 | K17: 0 | L17: 1 | M17: 0 | N17: w-302252-DebtReduction1-1DC-white | O17: 1DC | P17: white | Q17: TopLeft-302252 | R17: DebtReductionInc | T17: Missing | U17: 1 | W17: Missing | X17: 1 | Y17: Debt Settlement1 Master | Z17: LA | AA17: 10001-15000 | AB17: Yahoo | AC17: search.yahoo.com | AD17: DebtReductionInc | AE17: Get Out Of Debt | AF17: Unknown
A18: LQ-1AE81972345C497C | B18: 39939 | C18: 39939 | D18: 39937 | E18: 39934 | F18: 34 | G18: Unknown | H18: Unknown | I18: 0 | J18: 0 | K18: 0 | L18: 1 | M18: 0 | N18: w-302252-DebtReduction1-1DC-Head3 | O18: 1DC | P18: Head3 | Q18: TopLeft-302252 | R18: DebtReductionInc | T18: Missing | U18: 1 | W18: Missing | X18: 1 | Y18: Debt Settlement1 Master | Z18: NY | AA18: 30001-50000 | AB18: Yahoo | AC18: search.yahoo.com | AD18: DebtReductionInc | AE18: General Debt | AF18: Unknown
A19: LQ-254A87EF05F80505 | B19: 39961 | C19: 39961 | D19: 39958 | E19: 39934 | F19: 56 | G19: Unknown | H19: Unknown | I19: 0 | J19: 0 | K19: 0 | L19: 1 | M19: 0 | N19: w-302252-DebtReduction1-1DC-white | O19: 1DC | P19: white | Q19: TopLeft-302252 | R19: DebtReductionInc | T19: Missing | U19: 1 | W19: Missing | X19: 1 | Y19: Debt Settlement1 Master | Z19: NV | AA19: 50001-70000 | AB19: Yahoo | AC19: search.yahoo.com | AD19: DebtReductionInc | AE19: Lower Payments | AF19: Unknown
A20: LQ-39F9A3A43DA564A4 | B20: 39922 | C20: 39922 | D20: 39916 | E20: 39904 | F20: 17 | G20: Unknown | H20: Unknown | I20: 0 | J20: 0 | K20: 0 | L20: 1 | M20: 0 | N20: w-302252-DebtReduction1-1DC-BlueMeter | O20: 1DC | P20: BlueMeter | Q20: TopLeft-302252 | R20: DebtReductionInc | T20: Missing | U20: 1 | W20: Missing | X20: 1 | Y20: Debt Settlement1 Master | Z20: IL | AA20: 7500-15000 | AB20: Yahoo | AC20: search.yahoo.com | AD20: DebtReductionInc | AE20: General Debt | AF20: Unknown
A21: LQ-908B338CCAE7AF07 | B21: 40026 | C21: 40026 | D21: 40021 | E21: 40026 | F21: 121 | G21: Unable to contact - Bad Contact Information | H21: Bad quality | I21: 0 | J21: 0 | K21: 1 | L21: 0 | M21: 0 | N21: w-302252-DebtReduction1-1DC-CreditSolutions | O21: 1DC | P21: CreditSolutions | Q21: TopLeft-302252 | R21: DebtReductionInc | S21: 3 | T21: Medium (3-4) | U21: 0 | V21: 3 | W21: Medium (3-4) | X21: 0 | Y21: creditsolutions-branded-shortform | Z21: IL | AA21: 7500-10000 | AB21: Google | AC21: googleads.g.doubleclick.net | AD21: DebtReductionInc | AE21: Credit Card Debt - high volume | AF21: Unknown
A22: LQ-363836230D3B7F05 | B22: 40079 | C22: 40079 | D22: 40077 | E22: 40057 | F22: 174 | G22: Unknown | H22: Unknown | I22: 0 | J22: 0 | K22: 0 | L22: 1 | M22: 0 | N22: w-302252-DebtReduction1-1DC-white | O22: 1DC | P22: white | Q22: TopLeft-302252 | R22: DebtReductionInc | S22: 5 | T22: High (5) | U22: 0 | V22: 5 | W22: High (5) | X22: 0 | Y22: Debt Settlement1 Master | Z22: MT | AA22: 30001-50000 | AB22: Google | AC22: ezinearticles.com | AD22: DebtReductionInc | AE22: Credit Card Debt - high volume | AF22: Unknown
A23: LQ-950B64DAAE4D6A70 | B23: 39952 | C23: 39952 | D23: 39951 | E23: 39934 | F23: 47 | G23: Unknown | H23: Unknown | I23: 0 | J23: 0 | K23: 0 | L23: 1 | M23: 0 | N23: w-302252-DebtReduction1-1DC-white | O23: 1DC | P23: white | Q23: TopLeft-302252 | R23: DebtReductionInc | T23: Missing | U23: 1 | W23: Missing | X23: 1 | Y23: Debt Settlement1 Master | Z23: MT | AA23: More_than_100000 | AB23: Yahoo | AC23: www.findstuff.com | AD23: state | AE23: Consolidation Debt Loan | AF23: Unknown
A24: LQ-DF5088B1D90CE898 | B24: 39913 | C24: 39913 | D24: 39909 | E24: 39904 | F24: 8 | G24: Unknown | H24: Unknown | I24: 0 | J24: 0 | K24: 0 | L24: 1 | M24: 0 | N24: w-302252-DebtReduction1-2DC-BlueMeter | O24: 2DC | P24: BlueMeter | Q24: TopLeft-302252 | R24: DebtReductionInc | T24: Missing | U24: 1 | W24: Missing | X24: 1 | Y24: Debt Settlement1 Master | Z24: MO | AA24: 7500-15000 | AB24: AdKnowledge | AC24: us.mc631.mail.yahoo.com | AD24: Financial Services | AE24: Consolidate | AF24: Unknown
A25: LQ-0087EB6E27F1B279 | B25: 39922 | C25: 39922 | D25: 39916 | E25: 39904 | F25: 17 | G25: Unknown | H25: Unknown | I25: 0 | J25: 0 | K25: 0 | L25: 1 | M25: 0 | N25: w-302252-DebtReduction1-1DC | O25: 1DC | P25: Base / unspecified | Q25: TopLeft-302252 | R25: DebtReductionInc | T25: Missing | U25: 1 | W25: Missing | X25: 1 | Y25: Debt Settlement1 Master | Z25: MD | AA25: More_than_100000 | AB25: Yahoo | AC25: search.yahoo.com | AD25: state | AE25: Bankruptcy And Chapter 7 | AF25: Unknown
A26: LQ-D893CF50558388F2 | B26: 39947 | C26: 39947 | D26: 39944 | E26: 39934 | F26: 42 | G26: Unable to contact - Bad Contact Information | H26: Bad quality | I26: 0 | J26: 0 | K26: 1 | L26: 0 | M26: 0 | N26: w-302252-DebtReduction1-1DC-white | O26: 1DC | P26: white | Q26: TopLeft-302252 | R26: DebtReductionInc | T26: Missing | U26: 1 | W26: Missing | X26: 1 | Y26: Debt Settlement1 Master | Z26: TX | AA26: More_than_100000 | AB26: Yahoo | AC26: search.yahoo.com | AD26: DebtReductionInc | AE26: Debt Consolidation | AF26: Unknown
A27: LQ-04C528C5A59D2414 | B27: 39930 | C27: 39930 | D27: 39930 | E27: 39904 | F27: 25 | G27: Unknown | H27: Unknown | I27: 0 | J27: 0 | K27: 0 | L27: 1 | M27: 0 | N27: w-302252-DebtReduction1-1DC-BlueMeter | O27: 1DC | P27: BlueMeter | Q27: TopLeft-302252 | R27: DebtReductionInc | T27: Missing | U27: 1 | W27: Missing | X27: 1 | Y27: Debt Settlement1 Master | Z27: CA | AA27: 7500-15000 | AB27: Google | AC27: www.google.com | AD27: Debt General | AE27: Student Debt | AF27: Defaulted student loans
A28: LQ-6D4816146BE1C143 | B28: 40003 | C28: 40003 | D28: 40000 | E28: 39995 | F28: 98 | G28: Unknown | H28: Unknown | I28: 0 | J28: 0 | K28: 0 | L28: 1 | M28: 0 | N28: w-302252-DebtReduction1-1DC-CreditSolutions | O28: 1DC | P28: CreditSolutions | Q28: TopLeft-302252 | R28: DebtReductionInc | T28: Missing | U28: 1 | V28: 2 | W28: Low (1-2) | X28: 0 | Y28: creditsolutions-branded-shortform | Z28: CA | AA28: 30001-50000 | AB28: Google | AC28: www.google.com | AD28: Debt Holding Tank | AE28: Holding Tank - Debt | AF28: American debt
A29: LQ-857242788DF98B0B | B29: 39914 | C29: 39914 | D29: 39909 | E29: 39904 | F29: 9 | G29: Closed | H29: Closed | I29: 1 | J29: 0 | K29: 0 | L29: 0 | M29: 1 | N29: w-302252-DebtReduction1-2DC-BlueMeter | O29: 2DC | P29: BlueMeter | Q29: TopLeft-302252 | R29: DebtReductionInc | T29: Missing | U29: 1 | W29: Missing | X29: 1 | Y29: Debt Settlement1 Master | Z29: IL | AA29: 70001-90000 | AB29: Google | AC29: www.google.com | AD29: Debt Holding Tank | AE29: Holding Tank - Debt | AF29: Debt stoppers
A30: LQ-26EBF0D848A9D139 | B30: 40020 | C30: 40020 | D30: 40014 | E30: 39995 | F30: 115 | G30: Unknown | H30: Unknown | I30: 0 | J30: 0 | K30: 0 | L30: 1 | M30: 0 | N30: w-302252-DebtReduction1-1DC-CreditSolutions | O30: 1DC | P30: CreditSolutions | Q30: TopLeft-302252 | R30: DebtReductionInc | S30: 5 | T30: High (5) | U30: 0 | V30: 2 | W30: Low (1-2) | X30: 0 | Y30: creditsolutions-branded-shortform | Z30: MO | AA30: 30001-50000 | AB30: Google | AC30: pagead2.googlesyndication.com | AD30: DebtReductionInc | AE30: Credit Card Debt - high volume | AF30: Unknown
A31: LQ-E478C6B346995DD3 | B31: 40001 | C31: 40001 | D31: 40000 | E31: 39995 | F31: 96 | G31: Unknown | H31: Unknown | I31: 0 | J31: 0 | K31: 0 | L31: 1 | M31: 0 | N31: w-302252-DebtReduction1-1DC-yellowarrow-blue | O31: 1DC | P31: yellowarrow-blue | Q31: TopLeft-302252 | R31: DebtReductionInc | T31: Missing | U31: 1 | V31: 3 | W31: Medium (3-4) | X31: 0 | Y31: Debt Settlement1 Master | Z31: TX | AA31: 10001-15000 | AB31: Google | AC31: businessmajors.about.com | AD31: DebtReductionInc | AE31: Student Debt | AF31: Unknown
A32: LQ-737AB5FF9653E346 | B32: 40072 | C32: 40072 | D32: 40070 | E32: 40057 | F32: 167 | G32: Unknown | H32: Unknown | I32: 0 | J32: 0 | K32: 0 | L32: 1 | M32: 0 | N32: w-302252-DebtReduction1-1DC-CreditSolutions | O32: 1DC | P32: CreditSolutions | Q32: TopLeft-302252 | R32: DebtReductionInc | S32: 5 | T32: High (5) | U32: 0 | V32: 4 | W32: Medium (3-4) | X32: 0 | Y32: creditsolutions-branded-shortform | Z32: MA | AA32: 7500-10000 | AB32: Google | AC32: www.google.com | AD32: Debt General | AE32: Loan Default | AF32: Loan default help
A33: LQ-29D1799F1878B804 | B33: 39938 | C33: 39938 | D33: 39937 | E33: 39934 | F33: 33 | G33: Unknown | H33: Unknown | I33: 0 | J33: 0 | K33: 0 | L33: 1 | M33: 0 | N33: w-302252-DebtReduction1-1DC-BlueMeter | O33: 1DC | P33: BlueMeter | Q33: TopLeft-302252 | R33: DebtReductionInc | T33: Missing | U33: 1 | W33: Missing | X33: 1 | Y33: Debt Settlement1 Master | Z33: MO | AA33: More_than_100000 | AB33: Google | AC33: www.google.com | AD33: Debt General | AE33: Student Debt | AF33: Student loan default
A34: LQ-BE8BCD9469755BA4 | B34: 39927 | C34: 39927 | D34: 39923 | E34: 39904 | F34: 22 | G34: Unknown | H34: Unknown | I34: 0 | J34: 0 | K34: 0 | L34: 1 | M34: 0 | N34: w-302252-DebtReduction1-1DC-BlueMeter | O34: 1DC | P34: BlueMeter | Q34: TopLeft-302252 | R34: DebtReductionInc | T34: Missing | U34: 1 | W34: Missing | X34: 1 | Y34: Debt Settlement1 Master | Z34: FL | AA34: 30001-50000 | AB34: Google | AC34: googleads.g.doubleclick.net | AD34: DebtReductionInc | AE34: Stop Collections | AF34: Unknown
A35: LQ-4A9F78894EECDCCC | B35: 40026 | C35: 40026 | D35: 40021 | E35: 40026 | F35: 121 | G35: Unknown | H35: Unknown | I35: 0 | J35: 0 | K35: 0 | L35: 1 | M35: 0 | N35: w-302252-DebtReduction1-1DC-CreditSolutions | O35: 1DC | P35: CreditSolutions | Q35: TopLeft-302252 | R35: DebtReductionInc | S35: 1 | T35: Low (1-2) | U35: 0 | V35: 5 | W35: High (5) | X35: 0 | Y35: creditsolutions-branded-shortform | Z35: NY | AA35: 20001-30000 | AB35: Yahoo | AC35: www.bediddle.com | AD35: DebtReductionInc | AE35: Debt Consolidation | AF35: Unknown
A36: LQ-39B371B8EEA27E1B | B36: 40023 | C36: 40023 | D36: 40021 | E36: 39995 | F36: 118 | G36: Unknown | H36: Unknown | I36: 0 | J36: 0 | K36: 0 | L36: 1 | M36: 0 | N36: w-302252-DebtReduction1-1DC-CreditSolutions | O36: 1DC | P36: CreditSolutions | Q36: TopLeft-302252 | R36: DebtReductionInc | S36: 1 | T36: Low (1-2) | U36: 0 | V36: 5 | W36: High (5) | X36: 0 | Y36: creditsolutions-branded-shortform | Z36: AZ | AA36: 10001-15000 | AB36: Google | AC36: googleads.g.doubleclick.net | AD36: DebtReductionInc | AE36: Credit Card Debt - high volume | AF36: Unknown
A37: LQ-BD07C4CF8B0E3BF4 | B37: 39979 | C37: 39979 | D37: 39979 | E37: 39965 | F37: 74 | G37: Contacted - Doesn't Qualify | H37: Bad quality | I37: 0 | J37: 0 | K37: 1 | L37: 0 | M37: 0 | N37: w-302252-DebtReduction1-1DC | O37: 1DC | P37: Base / unspecified | Q37: TopLeft-302252 | R37: DebtReductionInc | T37: Missing | U37: 1 | W37: Missing | X37: 1 | Y37: Debt Settlement1 Master | Z37: TX | AA37: 20001-30000 | AB37: AdKnowledge | AC37: intellimatch.org | AD37: Financial Services | AE37: Consolidate | AF37: Unknown
A38: LQ-990E78AF9279307A | B38: 40022 | C38: 40022 | D38: 40021 | E38: 39995 | F38: 117 | G38: Unknown | H38: Unknown | I38: 0 | J38: 0 | K38: 0 | L38: 1 | M38: 0 | N38: w-302252-DebtReduction1-1DC-CreditSolutions | O38: 1DC | P38: CreditSolutions | Q38: TopLeft-302252 | R38: DebtReductionInc | S38: 5 | T38: High (5) | U38: 0 | V38: 3 | W38: Medium (3-4) | X38: 0 | Y38: creditsolutions-branded-shortform | Z38: FL | AA38: 10001-15000 | AB38: Yahoo | AC38: search.yahoo.com | AD38: DebtReductionInc | AE38: Lower Payments | AF38: Unknown
A39: LQ-CA5027A88C4555CB | B39: 40044 | C39: 40044 | D39: 40042 | E39: 40026 | F39: 139 | G39: Unknown | H39: Unknown | I39: 0 | J39: 0 | K39: 0 | L39: 1 | M39: 0 | N39: w-302252-DebtReduction1-1DC-white | O39: 1DC | P39: white | Q39: TopLeft-302252 | R39: DebtReductionInc | S39: 5 | T39: High (5) | U39: 0 | V39: 5 | W39: High (5) | X39: 0 | Y39: Debt Settlement1 Master | Z39: IN | AA39: 7500-10000 | AB39: Google | AC39: www.usatoday.com | AD39: Debt General | AE39: Loan Default | AF39: Loans in default
A40: LQ-1B340E326AB0F098 | B40: 39926 | C40: 39926 | D40: 39923 | E40: 39904 | F40: 21 | G40: Unknown | H40: Unknown | I40: 0 | J40: 0 | K40: 0 | L40: 1 | M40: 0 | N40: w-302252-DebtReduction1-2DC-CreditSolutions | O40: 2DC | P40: CreditSolutions | Q40: TopLeft-302252 | R40: DebtReductionInc | T40: Missing | U40: 1 | W40: Missing | X40: 1 | Y40: creditsolutions-branded-shortform | Z40: CA | AA40: 20001-30000 | AB40: Yahoo | AC40: search.yahoo.com | AD40: DebtReductionInc | AE40: General Debt | AF40: Unknown
...

Sheet PQ Staging
A1: Privacy-safe staging table. Excel Power Query performs the remaining transformations.
A3: LeadKey | B3: LeadCreated | C3: CallStatus | D3: WidgetName | E3: PublisherZoneName | F3: PublisherCampaignName | G3: AddressScore | H3: PhoneScore | I3: AdvertiserCampaignName | J3: State | K3: DebtLevel | L3: Partner | M3: ReferralDomain | N3: MarketingCampaign | O3: AdGroup | P3: Keyword
A4: LQ-D0054C82A74FA8B8 | B4: 39995 | D4: w-302252-DebtReduction1-1DC-CreditSolutions | E4: TopLeft-302252 | F4: DebtReductionInc | H4: 5 | I4: creditsolutions-branded-shortform | J4: HI | K4: 30001-50000 | L4: google | M4: www.google.com | N4: Debt Holding Tank | O4: Holding Tank - Debt | P4: Debt specialists
A5: LQ-27965EA801BA046F | B5: 39916 | D5: w-300250-DebtReduction1-1DC-Head2 | E5: TopLeft-302252 | F5: DebtReductionInc | I5: Debt Settlement1 Master | J5: AL | K5: 90000-100000 | L5: AdKnowledge | N5: Financial Services | O5: Consolidate
A6: LQ-38BE97E34DFD8509 | B6: 39924 | C6: Unable to contact - Bad Contact Information | D6: w-300250-DebtReduction1-1DC-Head2 | E6: TopLeft-302252 | F6: DebtReductionInc | I6: Debt Settlement1 Master | J6: NY | K6: 20001-30000 | L6: AdKnowledge | M6: us.mc582.mail.yahoo.com | N6: Financial Services | O6: Consolidate
A7: LQ-FF0557178162A589 | B7: 40028 | C7: Contacted - Doesn't Qualify | D7: w-302252-DebtReduction1-1DC-white | E7: TopLeft-302252 | F7: DebtReductionInc | G7: 5 | H7: 3 | I7: Debt Settlement1 Master | J7: WA | K7: 20001-30000 | L7: Google | M7: norwich.kijiji.com | N7: DebtReductionInc | O7: Lower Payments
A8: LQ-0F1EB50543FFF1B9 | B8: 39916 | D8: w-300250-DebtReduction1-1DC-BlueMeter | E8: TopLeft-302252 | F8: DebtReductionInc | I8: Debt Settlement1 Master | J8: TX | K8: More_than_100000 | L8: Google | N8: DebtReductionInc | O8: Debt Reduction
A9: LQ-7264D0BE150739B2 | B9: 40023 | D9: w-302252-DebtReduction1-1DC-white | E9: TopLeft-302252 | F9: DebtReductionInc | G9: 5 | H9: 3 | I9: Debt Settlement1 Master | J9: CO | K9: 10001-15000 | L9: Google | M9: googleads.g.doubleclick.net | N9: DebtReductionInc | O9: Credit Card Debt - high volume
A10: LQ-DDC8A88AB95B9603 | B10: 40000 | D10: w-302252-DebtReduction1-1DC-white | E10: TopLeft-302252 | F10: DebtReductionInc | H10: 4 | I10: Debt Settlement1 Master | J10: MI | K10: 70001-90000 | L10: Google | M10: googleads.g.doubleclick.net | N10: DebtReductionInc | O10: Student Debt
A11: LQ-9A6852DEC3381AFC | B11: 39925 | C11: Unable to contact - Bad Contact Information | D11: w-300250-DebtReduction1-2DC-BlueMeter | E11: TopLeft-302252 | F11: DebtReductionInc | I11: Debt Settlement1 Master | J11: IA | K11: 7500-15000 | L11: google | M11: www.google.com | N11: Credit | O11: Debt Credit Services | P11: Credit services
A12: LQ-742F04170337A31C | B12: 39938 | D12: w-300250-DebtReduction1-1DC-Head3 | E12: TopLeft-302252 | F12: DebtReductionInc | I12: Debt Settlement1 Master | J12: LA | K12: 20001-30000 | L12: yahoo | M12: dir.yahoo.com | N12: DebtReductionInc | O12: Debt Consolidation
A13: LQ-1C6E4B5F99D1DD71 | B13: 40032 | D13: w-302252-DebtReduction1-1DC-CreditSolutions | E13: TopLeft-302252 | F13: DebtReductionInc | G13: 3 | H13: 4 | I13: creditsolutions-branded-shortform | J13: MI | K13: 10001-15000 | L13: google | M13: www.docstoc.com | N13: Debt Volume_MI | O13: Settlement | P13: Debt settlement
A14: LQ-A341D8692CD03D91 | B14: 39965 | C14: Unable to contact - Bad Contact Information | D14: w-302252-DebtReduction1-1DC-CreditSolutions | E14: TopLeft-302252 | F14: DebtReductionInc | I14: creditsolutions-branded-shortform | J14: TX | K14: 20001-30000 | L14: Google | M14: googleads.g.doubleclick.net | N14: DebtReductionInc | O14: Credit Card Debt - high volume
A15: LQ-D322F0EE3EE5476A | B15: 40020 | D15: w-302252-DebtReduction1-1DC-CreditSolutions | E15: TopLeft-302252 | F15: DebtReductionInc | G15: 5 | H15: 5 | I15: creditsolutions-branded-shortform | J15: IL | K15: 30001-50000 | L15: google | M15: www.google.com | N15: Debt Volume | O15: Debt | P15: Debt
A16: LQ-E477F03E3D0A0344 | B16: 39957 | D16: w-302252-DebtReduction1-1DC | E16: TopLeft-302252 | F16: DebtReductionInc | I16: Debt Settlement1 Master | J16: MI | K16: 15001-20000 | L16: yahoo | M16: search.yahoo.com | N16: state | O16: Debt Settlement Companies
A17: LQ-3429F31F72D06F42 | B17: 39957 | D17: w-302252-DebtReduction1-1DC-white | E17: TopLeft-302252 | F17: DebtReductionInc | I17: Debt Settlement1 Master | J17: LA | K17: 10001-15000 | L17: yahoo | M17: search.yahoo.com | N17: DebtReductionInc | O17: Get Out Of Debt
A18: LQ-1AE81972345C497C | B18: 39939 | D18: w-300250-DebtReduction1-1DC-Head3 | E18: TopLeft-302252 | F18: DebtReductionInc | I18: Debt Settlement1 Master | J18: NY | K18: 30001-50000 | L18: yahoo | M18: search.yahoo.com | N18: DebtReductionInc | O18: General Debt
A19: LQ-254A87EF05F80505 | B19: 39961 | D19: w-302252-DebtReduction1-1DC-white | E19: TopLeft-302252 | F19: DebtReductionInc | I19: Debt Settlement1 Master | J19: NV | K19: 50001-70000 | L19: yahoo | M19: search.yahoo.com | N19: DebtReductionInc | O19: Lower Payments
A20: LQ-39F9A3A43DA564A4 | B20: 39922 | D20: w-300250-DebtReduction1-1DC-BlueMeter | E20: TopLeft-302252 | F20: DebtReductionInc | I20: Debt Settlement1 Master | J20: IL | K20: 7500-15000 | L20: yahoo | M20: search.yahoo.com | N20: DebtReductionInc | O20: General Debt
A21: LQ-908B338CCAE7AF07 | B21: 40026 | C21: Unable to contact - Bad Contact Information | D21: w-302252-DebtReduction1-1DC-CreditSolutions | E21: TopLeft-302252 | F21: DebtReductionInc | G21: 3 | H21: 3 | I21: creditsolutions-branded-shortform | J21: IL | K21: 7500-10000 | L21: Google | M21: googleads.g.doubleclick.net | N21: DebtReductionInc | O21: Credit Card Debt - high volume
A22: LQ-363836230D3B7F05 | B22: 40079 | D22: w-302252-DebtReduction1-1DC-white | E22: TopLeft-302252 | F22: DebtReductionInc | G22: 5 | H22: 5 | I22: Debt Settlement1 Master | J22: MT | K22: 30001-50000 | L22: Google | M22: ezinearticles.com | N22: DebtReductionInc | O22: Credit Card Debt - high volume
A23: LQ-950B64DAAE4D6A70 | B23: 39952 | D23: w-302252-DebtReduction1-1DC-white | E23: TopLeft-302252 | F23: DebtReductionInc | I23: Debt Settlement1 Master | J23: MT | K23: More_than_100000 | L23: yahoo | M23: www.findstuff.com | N23: state | O23: Consolidation Debt Loan
A24: LQ-DF5088B1D90CE898 | B24: 39913 | D24: w-300250-DebtReduction1-2DC-BlueMeter | E24: TopLeft-302252 | F24: DebtReductionInc | I24: Debt Settlement1 Master | J24: MO | K24: 7500-15000 | L24: AdKnowledge | M24: us.mc631.mail.yahoo.com | N24: Financial Services | O24: Consolidate
A25: LQ-0087EB6E27F1B279 | B25: 39922 | D25: w-300250-DebtReduction1-1DC | E25: TopLeft-302252 | F25: DebtReductionInc | I25: Debt Settlement1 Master | J25: MD | K25: More_than_100000 | L25: yahoo | M25: search.yahoo.com | N25: state | O25: Bankruptcy And Chapter 7
A26: LQ-D893CF50558388F2 | B26: 39947 | C26: Unable to contact - Bad Contact Information | D26: w-302252-DebtReduction1-1DC-white | E26: TopLeft-302252 | F26: DebtReductionInc | I26: Debt Settlement1 Master | J26: TX | K26: More_than_100000 | L26: yahoo | M26: search.yahoo.com | N26: DebtReductionInc | O26: Debt Consolidation
A27: LQ-04C528C5A59D2414 | B27: 39930 | D27: w-300250-DebtReduction1-1DC-BlueMeter | E27: TopLeft-302252 | F27: DebtReductionInc | I27: Debt Settlement1 Master | J27: CA | K27: 7500-15000 | L27: google | M27: www.google.com | N27: Debt General | O27: Student Debt | P27: Defaulted student loans
A28: LQ-6D4816146BE1C143 | B28: 40003 | D28: w-302252-DebtReduction1-1DC-CreditSolutions | E28: TopLeft-302252 | F28: DebtReductionInc | H28: 2 | I28: creditsolutions-branded-shortform | J28: CA | K28: 30001-50000 | L28: google | M28: www.google.com | N28: Debt Holding Tank | O28: Holding Tank - Debt | P28: American debt
A29: LQ-857242788DF98B0B | B29: 39914 | C29: Closed | D29: w-300250-DebtReduction1-2DC-BlueMeter | E29: TopLeft-302252 | F29: DebtReductionInc | I29: Debt Settlement1 Master | J29: IL | K29: 70001-90000 | L29: google | M29: www.google.com | N29: Debt Holding Tank | O29: Holding Tank - Debt | P29: Debt stoppers
A30: LQ-26EBF0D848A9D139 | B30: 40020 | D30: w-302252-DebtReduction1-1DC-CreditSolutions | E30: TopLeft-302252 | F30: DebtReductionInc | G30: 5 | H30: 2 | I30: creditsolutions-branded-shortform | J30: MO | K30: 30001-50000 | L30: Google | M30: pagead2.googlesyndication.com | N30: DebtReductionInc | O30: Credit Card Debt - high volume
A31: LQ-E478C6B346995DD3 | B31: 40001 | D31: w-302252-DebtReduction1-1DC-yellowarrow-blue | E31: TopLeft-302252 | F31: DebtReductionInc | H31: 3 | I31: Debt Settlement1 Master | J31: TX | K31: 10001-15000 | L31: Google | M31: businessmajors.about.com | N31: DebtReductionInc | O31: Student Debt
A32: LQ-737AB5FF9653E346 | B32: 40072 | D32: w-302252-DebtReduction1-1DC-CreditSolutions | E32: TopLeft-302252 | F32: DebtReductionInc | G32: 5 | H32: 4 | I32: creditsolutions-branded-shortform | J32: MA | K32: 7500-10000 | L32: google | M32: www.google.com | N32: Debt General | O32: Loan Default | P32: Loan default help
A33: LQ-29D1799F1878B804 | B33: 39938 | D33: w-300250-DebtReduction1-1DC-BlueMeter | E33: TopLeft-302252 | F33: DebtReductionInc | I33: Debt Settlement1 Master | J33: MO | K33: More_than_100000 | L33: google | M33: www.google.com | N33: Debt General | O33: Student Debt | P33: Student loan default
A34: LQ-BE8BCD9469755BA4 | B34: 39927 | D34: w-300250-DebtReduction1-1DC-BlueMeter | E34: TopLeft-302252 | F34: DebtReductionInc | I34: Debt Settlement1 Master | J34: FL | K34: 30001-50000 | L34: Google | M34: googleads.g.doubleclick.net | N34: DebtReductionInc | O34: Stop Collections
A35: LQ-4A9F78894EECDCCC | B35: 40026 | D35: w-302252-DebtReduction1-1DC-CreditSolutions | E35: TopLeft-302252 | F35: DebtReductionInc | G35: 1 | H35: 5 | I35: creditsolutions-branded-shortform | J35: NY | K35: 20001-30000 | L35: yahoo | M35: www.bediddle.com | N35: DebtReductionInc | O35: Debt Consolidation
A36: LQ-39B371B8EEA27E1B | B36: 40023 | D36: w-302252-DebtReduction1-1DC-CreditSolutions | E36: TopLeft-302252 | F36: DebtReductionInc | G36: 1 | H36: 5 | I36: creditsolutions-branded-shortform | J36: AZ | K36: 10001-15000 | L36: Google | M36: googleads.g.doubleclick.net | N36: DebtReductionInc | O36: Credit Card Debt - high volume
A37: LQ-BD07C4CF8B0E3BF4 | B37: 39979 | C37: Contacted - Doesn't Qualify | D37: w-302252-DebtReduction1-1DC | E37: TopLeft-302252 | F37: DebtReductionInc | I37: Debt Settlement1 Master | J37: TX | K37: 20001-30000 | L37: AdKnowledge | M37: intellimatch.org | N37: Financial Services | O37: Consolidate
A38: LQ-990E78AF9279307A | B38: 40022 | D38: w-302252-DebtReduction1-1DC-CreditSolutions | E38: TopLeft-302252 | F38: DebtReductionInc | G38: 5 | H38: 3 | I38: creditsolutions-branded-shortform | J38: FL | K38: 10001-15000 | L38: yahoo | M38: search.yahoo.com | N38: DebtReductionInc | O38: Lower Payments
A39: LQ-CA5027A88C4555CB | B39: 40044 | D39: w-302252-DebtReduction1-1DC-white | E39: TopLeft-302252 | F39: DebtReductionInc | G39: 5 | H39: 5 | I39: Debt Settlement1 Master | J39: IN | K39: 7500-10000 | L39: google | M39: www.usatoday.com | N39: Debt General | O39: Loan Default | P39: Loans in default
A40: LQ-1B340E326AB0F098 | B40: 39926 | D40: w-300250-DebtReduction1-2DC-CreditSolutions | E40: TopLeft-302252 | F40: DebtReductionInc | I40: creditsolutions-branded-shortform | J40: CA | K40: 20001-30000 | L40: yahoo | M40: search.yahoo.com | N40: DebtReductionInc | O40: General Debt
A41: LQ-843FB6FDF8B0A1EA | B41: 40044 | D41: w-302252-DebtReduction1-1DC-yellowarrow-dark | E41: TopLeft-302252 | F41: DebtReductionInc | G41: 5 | H41: 3 | I41: Debt Settlement1 Master | J41: LA | K41: More_than_100000 | L41: AdKnowledge | M41: us.mc558.mail.yahoo.com | N41: Financial Services | O41: Consolidate
...

Sheet ReadMe
A2: Workbook guide
A4: Section | B4: Purpose
A5: Exec Summary | B5: Headline answer, key findings, and next steps.
A6: Data Cleaning | B6: Power Query transformations and formula-driven validation of the sanitized lead table.
A7: Trends | B7: Monthly and weekly close rates, Wilson intervals, target line, and significance tests.
A8: Segments | B8: Reliable ad-group view plus all reliable segment comparisons (n >= 75).
A9: Opportunity | B9: Formula-driven target arithmetic and three non-additive scenarios that reach 9.6%.
A10: Model | B10: Adjusted association estimates, fit diagnostics, holdout performance, and bootstrap stability.
A11: QA | B11: Terminal reconciliation and privacy checks. No other sheet depends on QA.
A12: Clean Leads | B12: Sanitized analytical source. Direct identifiers and detailed URLs are absent.
A13: PQ Staging | B13: Privacy-safe input table used by the workbook's LeadQualityCleaning Power Query.
A14: Source | B14: Analyst case-study workbook supplied by the recruiter; assignment definitions are retained in project documentation.
A15: Method note | B15: Detail
... A22: Commercial note | B22: The assignment states both a 20% CPL increase and $30 to $33. The workbook uses explicit $33 and notes $36 as sensitivity.
